Workbook

Sheet ĐẦU VÀO
A2: ĐẦU VÀO | B2: MẬT ĐỘ XÂY DỰNG
D3: MẬT ĐỘ ĐẤT | E3: DIỆN TÍCH XD
B4: ĐẤT | C4: 4420 | D4: 50 | E4: =C4*D4/100 -> 2210
B5: Nhà trẻ | C5: 450 | E5: =D5*C4/100 -> 0
B6: Đất ở | C6: =C4-C5 -> 3970 | D6: =D4-D5 -> 50 | E6: =D6*C4/100 -> 2210
B9: DÂN SỐ
B10: QH
B13: HỆ SỐ SỬ DỤNG ĐẤT
B14: QH | C14: 13
A17: BẢNG TÍNH | B17: THANG MÁY | D17: TC CH/TM | E17: CẦN BỐ TRÍ
C18: =NHA_NOXH!F43 -> 420 | D18: 70 | E18: =C18/D18 -> 6
B21: DIỆN TÍCH CÂY XANH
B22: TỔNG | C22: =C6*0.2 -> 794
B25: DIỆN TÍCH HẠ TẦNG
B26: TỔNG | C26: =C6-E6-C22-HẦM!#REF! -> #REF!
A32: GHI CHÚ | B32: TIÊU CHUẨN | C32: SỐ ĐIỀN

Sheet CHỈ TIÊU QH
B1: STT | C1: HẠNG MỤC | D1: ĐƠN VỊ | E1: NHÀ Ở XÃ HỘI | F1: TRƯỜNG MẦM NON | G1: TỔNG | H1: So sánh với quy hoạch TMB 1/500 (công trình nhà ở xã hội ) | I1: Ghi chú
C2: DIỆN TÍCH SỬ DỤNG ĐẤT CỦA DỰ ÁN: 4.420M2
B3: 1 | C3: Diện tích đất | D3: m² | E3: =G3-F3 -> 3977 | F3: 420 | G3: 4397 | H3: 4397 | I3: Phù hợp | K3: =E3*20% -> 795.4
B4: 2 | C4: Diện tích xây dựng công trình | D4: m² | E4: 1708.7 | F4: 420 | H4: 1710 | I4: Phù hợp
C5: Phần đế | D5: m² | E5: =E4 -> 1708.7
C6: Phần tháp | D6: m² | E6: =NHA_NOXH!D32 -> 1433.1
C7: Diện tích xây dựng tầng hầm | D7: m² | E7: =HẦM!E5 -> 3600
B8: 3 | C8: Mật độ xây dựng | D8: % | E8: =E5/E3*100 -> 42.964546 | G8: =(E4+F4)/G3*100 -> 48.412554 | H8: 48.44 | I8: Phù hợp với mật độ gộp của ô đất
B9: 5 | C9: Tổng diện tích sàn nhà ở cao tầng | D9: m² | E9: =NHA_NOXH!D43 -> 65927.6 | F9: =420*3.3 -> 1386
B10: 4 | C10: Tổng diện tích sàn (phần nổi) | D10: m² | E10: =NHA_NOXH!O20 -> 51527.6 | H10: 51862 | I10: Phù hợp
B11: 5 | C11: Hệ số sử dụng đất | D11: Lần | E11: =NHA_NOXH!P20/E3 -> 12.65733
B12: 6 | C12: Tầng cao | D12: Tầng | E12: 35 | F12: 4 | H12: 35 | I12: Phù hợp
B13: 7 | C13: Tầng Hầm | D13: Tầng | E13: 4 | H13: 4 | I13: Phù hợp
C14: Diện tích sàn căn hộ NOXH | D14: m² | E14: =NHA_NOXH!E43 -> 29265.6
C15: Diện tích sàn dịch vụ thương mại | D15: m² | E15: ='TẦNG 1-6(HH)'!H22 -> 5957.6
C16: Diện tích sàn công cộng ( SHCĐ) | D16: m² | E16: =NHA_NOXH!G34 -> 0
C17: Diện tích phụ trợ, tiện ích, kĩ thuật | D17: m² | E17: =+E10-E14-E15-E16 -> 16304.4
B18: 8 | C18: Tổng diện tích sàn xây dựng tầng hầm | D18: m² | E18: =HẦM!E6 -> 14400 | H18: 14400 | I18: Phù hợp | L18: =4397*20% -> 879.4
B19: 9 | C19: Diện tích đỗ xe | D19: m² | E19: =HẦM!I6 -> 12240
B20: 10 | C20: Diện tích sàn lánh nạn | D20: m² | E20: =NHA_NOXH!D20 -> 1433.1
B21: 11 | C21: Diện tích sàn tầng tum | D21: m² | E21: =NHA_NOXH!D3 -> 154 | H21: 430 | I21: Phù hợp
B22: 12 | C22: Số lượng căn hộ | D22: Căn hộ | E22: =NHA_NOXH!F43 -> 420 | H22: 420 | I22: Phù hợp
B23: 13 | C23: Dân số | D23: Người | E23: =NHA_NOXH!J43 -> 1288 | H23: 1288 | I23: Phù hợp
B24: 9 | C24: Tổng yêu cầu | E24: =HẦM!F22 -> 9630
B25: 10 | C25: Bao gồm xe máy | E25: =+E22*6 -> 2520
B26: 14 | C26: Diện tích cây xanh | D26: m² | E26: 792 | F26: 106 | G26: =F26+E26 -> 898
B27: 15 | C27: Diện tích sân đường nội bộ | D27: m² | E27: 1076
E32: =E10+E18 -> 65927.6
A33: Quy chuẩn

Sheet NHA_NOXH
A1: BẢNG THỐNG KÊ DIỆN TÍCH CÔNG TRÌNH VÀ CÁC CHỈ TIÊU CHÍNH (NOXH)
A2: Tầng | D2: GFA (m2) | E2: NSA (m2) | F2: Số căn hộ (căn) | G2: SHCĐ (m2) | H2: DVTM (m2) | I2: Số căn DV (căn) | J2: Dân Số | K2: Chiều cao | M2: Tầng cao | N2: Tầng ở
A3: THÁP | C3: Tum | D3: 154 | K3: 3
B4: TẦNG 7 - TẦNG 35 | C4: =C5+1 -> 35 | D4: 1433.1 | E4: =E5 -> 1045.2 | F4: =F5 -> 15 | J4: =J5 -> 46 | K4: 3.3 | L4: căn hộ | M4: =M5 -> 1 | N4: =N5 -> 1 | P4: =D4*30% -> 429.93
C5: =C6+1 -> 34 | D5: =D4 -> 1433.1 | E5: =E6 -> 1045.2 | F5: =F6 -> 15 | J5: =J6 -> 46 | K5: 3.3 | L5: căn hộ | M5: =M6 -> 1 | N5: =N6 -> 1
C6: =C7+1 -> 33 | D6: =D5 -> 1433.1 | E6: =E7 -> 1045.2 | F6: =F7 -> 15 | J6: =J7 -> 46 | K6: 3.3 | L6: căn hộ | M6: =M7 -> 1 | N6: =N7 -> 1
C7: =C8+1 -> 32 | D7: =D6 -> 1433.1 | E7: =E8 -> 1045.2 | F7: =F8 -> 15 | J7: =J8 -> 46 | K7: 3.3 | L7: căn hộ | M7: =M8 -> 1 | N7: =N8 -> 1 | S7: =SUM(H34:H38) -> 6037.8
C8: =C9+1 -> 31 | D8: =D7 -> 1433.1 | E8: =E9 -> 1045.2 | F8: =F9 -> 15 | J8: =J9 -> 46 | K8: 3.3 | L8: căn hộ | M8: =M9 -> 1 | N8: =N9 -> 1 | P8: =SUM(J4:J19)*0.3 -> 220.8
C9: =C10+1 -> 30 | D9: =D8 -> 1433.1 | E9: =E10 -> 1045.2 | F9: =F10 -> 15 | J9: =J10 -> 46 | K9: 3.3 | L9: căn hộ | M9: =M10 -> 1 | N9: =N10 -> 1 | S9: =S7/E43 -> 0.20631048
C10: =C11+1 -> 29 | D10: =D9 -> 1433.1 | E10: =E11 -> 1045.2 | F10: =F11 -> 15 | J10: =J11 -> 46 | K10: 3.3 | L10: căn hộ | M10: =M11 -> 1 | N10: =N11 -> 1
C11: =C12+1 -> 28 | D11: =D10 -> 1433.1 | E11: =E12 -> 1045.2 | F11: =F12 -> 15 | J11: =J12 -> 46 | K11: 3.3 | L11: căn hộ | M11: =M12 -> 1 | N11: =N12 -> 1
C12: =C13+1 -> 27 | D12: =D11 -> 1433.1 | E12: =E13 -> 1045.2 | F12: =F13 -> 15 | J12: =J13 -> 46 | K12: 3.3 | L12: căn hộ | M12: =M13 -> 1 | N12: =N13 -> 1
C13: =C14+1 -> 26 | D13: =D12 -> 1433.1 | E13: =E14 -> 1045.2 | F13: =F14 -> 15 | J13: =J14 -> 46 | K13: 3.3 | L13: căn hộ | M13: =M14 -> 1 | N13: =N14 -> 1 | O13: =SUM(D4:D32)-D20 -> 40126.8
C14: =C15+1 -> 25 | D14: =D13 -> 1433.1 | E14: =E15 -> 1045.2 | F14: =F15 -> 15 | J14: =J15 -> 46 | K14: 3.3 | L14: căn hộ | M14: =M15 -> 1 | N14: =N15 -> 1 | Q14: 1 | R14: =SUM(D4:D19) -> 22929.6
C15: =C16+1 -> 24 | D15: =D14 -> 1433.1 | E15: =E16 -> 1045.2 | F15: =F16 -> 15 | J15: =J16 -> 46 | K15: 3.3 | L15: căn hộ | M15: =M16 -> 1 | N15: =N16 -> 1 | Q15: 2 | R15: =SUM(D21:D32) -> 17197.2
C16: =C17+1 -> 23 | D16: =D15 -> 1433.1 | E16: =E17 -> 1045.2 | F16: =F17 -> 15 | J16: =J17 -> 46 | K16: 3.3 | L16: căn hộ | M16: =M17 -> 1 | N16: =N17 -> 1 | Q16: 3 | R16: =SUM(D33:D38) -> 9813.7
C17: =C18+1 -> 22 | D17: =D16 -> 1433.1 | E17: =E18 -> 1045.2 | F17: =F18 -> 15 | J17: =J18 -> 46 | K17: 3.3 | L17: căn hộ | M17: =M18 -> 1 | N17: =N18 -> 1 | Q17: A | R17: =R14+R15+R16 -> 49940.5
C18: =C19+1 -> 21 | D18: =D17 -> 1433.1 | E18: =E19 -> 1045.2 | F18: =F19 -> 15 | J18: =J19 -> 46 | K18: 3.3 | L18: căn hộ | M18: =M19 -> 1 | N18: =N19 -> 1
C19: =C20+1 -> 20 | D19: =D18 -> 1433.1 | E19: =E21 -> 1045.2 | F19: =F21 -> 15 | J19: =+J21 -> 46 | K19: 3.3 | L19: căn hộ | M19: =M20 -> 1 | N19: =N20 -> 1 | O19: sàn nổi
C20: =C21+1 -> 19 | D20: =D19 -> 1433.1 | E20: 0 | F20: 0 | G20: 397.7 | K20: 3.3 | L20: lánh nạn | M20: =M21 -> 1 | N20: =N21 -> 1 | O20: =SUM(D3:D38) -> 51527.6 | P20: =O20-D20-D3+G20 -> 50338.2 | Q20: =(R14+R15)/R17*100% -> 0.80349216
C21: =C22+1 -> 18 | D21: =D20 -> 1433.1 | E21: =E22 -> 1045.2 | F21: =F22 -> 15 | J21: =J22 -> 46 | K21: 3.3 | L21: căn hộ | M21: =M22 -> 1 | N21: =N22 -> 1 | T21: =SUM(D4:D19)+SUM(D21:D38) -> 49940.5
C22: =C23+1 -> 17 | D22: =D21 -> 1433.1 | E22: =E23 -> 1045.2 | F22: =F23 -> 15 | J22: =J23 -> 46 | K22: 3.3 | L22: căn hộ | M22: =M23 -> 1 | N22: =N23 -> 1 | O22: =O20/4397*100 -> 1171.8808 | P22: =P20/3977 -> 12.65733
C23: =C24+1 -> 16 | D23: =D22 -> 1433.1 | E23: =E24 -> 1045.2 | F23: =F24 -> 15 | J23: =J24 -> 46 | K23: 3.3 | L23: căn hộ | M23: =M24 -> 1 | N23: =N24 -> 1
C24: =C25+1 -> 15 | D24: =D23 -> 1433.1 | E24: =E25 -> 1045.2 | F24: =F25 -> 15 | J24: =J25 -> 46 | K24: 3.3 | L24: căn hộ | M24: =M25 -> 1 | N24: =N25 -> 1
C25: =C26+1 -> 14 | D25: =D24 -> 1433.1 | E25: =E27 -> 1045.2 | F25: =F26 -> 15 | J25: =J26 -> 46 | K25: 3.3 | L25: căn hộ | M25: =M26 -> 1 | N25: =N26 -> 1 | P25: =SUM(D4:D19)+SUM(D21:D38) -> 49940.5
C26: =C27+1 -> 13 | D26: =D25 -> 1433.1 | E26: =E27 -> 1045.2 | F26: =F27 -> 15 | J26: =J27 -> 46 | K26: 3.3 | L26: căn hộ | M26: =M27 -> 1 | N26: =N27 -> 1
C27: =C28+1 -> 12 | D27: =D26 -> 1433.1 | E27: =E28 -> 1045.2 | F27: =F28 -> 15 | J27: =J28 -> 46 | K27: 3.3 | L27: căn hộ | M27: =M28 -> 1 | N27: =N28 -> 1
C28: =C29+1 -> 11 | D28: =D27 -> 1433.1 | E28: =E29 -> 1045.2 | F28: =F29 -> 15 | J28: =J29 -> 46 | K28: 3.3 | L28: căn hộ | M28: =M29 -> 1 | N28: =N29 -> 1
C29: =C30+1 -> 10 | D29: =D28 -> 1433.1 | E29: =E30 -> 1045.2 | F29: =F30 -> 15 | J29: =J30 -> 46 | K29: 3.3 | L29: căn hộ | M29: =M30 -> 1 | N29: =N30 -> 1 | O29: =SUM(D33:D38) -> 9813.7 | T29: =SUM(D33:D38)/SUM(D4:D32) -> 0.23613387
C30: =C31+1 -> 9 | D30: =D29 -> 1433.1 | E30: =E31 -> 1045.2 | F30: =F31 -> 15 | J30: =J31 -> 46 | K30: 3.3 | L30: căn hộ | M30: =M31 -> 1 | N30: =N31 -> 1
C31: =C32+1 -> 8 | D31: =D30 -> 1433.1 | E31: =E32 -> 1045.2 | F31: =F32 -> 15 | J31: =J32 -> 46 | K31: 3.3 | L31: căn hộ | M31: =M32 -> 1 | N31: =N32 -> 1
C32: =C33+1 -> 7 | D32: =D31 -> 1433.1 | E32: ='TẦNG 7-35(NOXH) (2)'!C18 -> 1045.2 | F32: ='TẦNG 7-35(NOXH)'!C14 -> 15 | J32: ='TẦNG 7-35(NOXH)'!G14 -> 46 | K32: 3.3 | L32: căn hộ | M32: =M33 -> 1 | N32: 1 | P32: =SUM(H34:H38)-R34 -> 184.68
A33: ĐẾ | C33: =C34+1 -> 6 | D33: 1490 | K33: 6 | L33: tiện ích | M33: =M34 -> 1
C34: =C35+1 -> 5 | D34: 1708.7 | H34: ='TẦNG 1-6(HH)'!F22 -> 1165.9 | K34: 5 | L34: văn phòng | M34: =M35 -> 1 | R34: =SUM(E4:E32)*20% -> 5853.12
C35: =C36+1 -> 4 | D35: 1708.7 | H35: ='TẦNG 1-6(HH)'!E22 -> 1165.9 | K35: 5 | L35: văn phòng | M35: =M36 -> 1
C36: =C37+1 -> 3 | D36: =D38 -> 1666.8 | H36: ='TẦNG 1-6(HH)'!D22 -> 1304.6 | I36: =I38 -> 15 | K36: 3.9 | L36: shophouse | M36: =M37 -> 1 | R36: =H43-R34 -> 184.68
C37: =C38+1 -> 2 | D37: 1572.7 | H37: ='TẦNG 1-6(HH)'!C22 -> 1213.5 | I37: =I38 -> 15 | K37: 3.9 | L37: shophouse | M37: =M38 -> 1 | P37: =3970*90% -> 3573
C38: 1 | D38: 1666.8 | H38: ='TẦNG 1-6(HH)'!B22 -> 1187.9 | I38: 15 | K38: 6 | L38: shophouse | M38: =1 -> 1 | P38: =4000*90% -> 3600
A39: HẦM | C39: B1 | D39: 3600 | E39: =E40 -> 3060 | K39: 4.5 | L39: hầm để xe | N39: 25 m
C40: B2 | D40: =D39 -> 3600 | E40: =E41 -> 3060 | K40: 3.6 | L40: hầm để xe | S40: =SUM(H34:H38)/E43 -> 0.20631048
...

Sheet TẦNG 1-3
A1: BẢNG THỐNG KÊ TẦNG ĐIỂN HÌNH
A2: Tên căn | B2: Diện tích thông thủy (m2)/phòng | C2: Số lượng (căn) | D2: Diện tích thông thủy (m2)/tầng | E2: Tỷ lệ | F2: Loại căn
A3: Loại 1 | B3: 0 | C3: 0 | D3: =B3*C3 -> 0 | E3: =D3/D5 -> #DIV/0! | F3: 1PN
A4: Loại 4 | B4: 0 | C4: 0 | D4: =B4*C4 -> 0 | E4: =D4/D5 -> #DIV/0! | F4: 2PN
A5: Tổng | C5: =SUM(C3:C4) -> 0 | D5: =SUM(D3:D4) -> 0 | E5: =SUM(E3:E4) -> #DIV/0!
A6: Diện tích sàn tầng điển hình (m2) | D6: ='ĐẦU VÀO'!#REF! -> #REF!
A7: Hiệu suất sử dụng | D7: =D5/D6 -> #REF!

Sheet HẦM
A1: BẢNG TÍNH DIỆN TÍCH ĐỂ XE
A2: NỘI DUNG | B2: Diện tích sàn xây dựng (không tính tầng lánh nạn và tum) | C2: Tiêu chuẩn(%) theo quyết định 1218/QĐ UBND 2022 | D2: Diện tích để xe cần đáp ứng (m2) | E2: Trong nhà | M2: Ngoài trời
E3: Diện tích sàn tầng hầm theo phương án thiết kế (m2) | I3: Diện tích hữu dụng để xe theo phương án thiết kế (85% diện tích sàn hầm) (m2)
E4: B1 | F4: B2 | G4: B3 | H4: B4 | I4: B1 | J4: B2 | K4: B3 | L4: B4
A5: NOXH | B5: =NHA_NOXH!P25 -> 49940.5 | C5: 17 | D5: =B5*C5/100 -> 8489.885 | E5: 3600 | F5: =E5 -> 3600 | G5: =E5 -> 3600 | H5: =E5 -> 3600 | I5: =E5*0.85 -> 3060 | J5: =I5 -> 3060 | K5: =I5 -> 3060 | L5: =I5 -> 3060 | M5: 50
A6: TỔNG | D6: =D5 -> 8489.885 | E6: =E5+F5+G5+H5 -> 14400 | I6: =I5+J5+K5+L5 -> 12240
A9: TÍNH TOÁN SỐ LƯỢNG XE MÁY | D9: TIÊU CHUẨN | E9: YÊU CẦU | F9: PATK | G9: ĐÁP ỨNG | K9: ghi chú
A10: Tổng số lượng căn hộ | D10: =NHA_NOXH!F43+15 -> 435
A11: Diện tích xe máy/1 căn hộ | D11: 6 | E11: =D10*D11 -> 2610 | F11: =D10*D11 -> 2610 | K11: QCVN 04:2024/BXD
A12: Số lượng Slot để xe | D12: 3 | E12: =E11/D12 -> 870 | F12: =F11/D12 -> 870 | K12: TCVN 4451:2012
A13: Slot đỗ xe máy trong hầm
A14: Diện tích đỗ xe máy trong hầm tương ứng | D14: 3
A15: Slot đỗ xe máy ngoài hầm
A16: Diện tích đỗ xe máy ngoài hầm tương ứng | D16: 3
A17: Slot điểm sạc xe điện nếu có (30% tổng số xe máy) | D17: 0.3 | E17: =E12*D17 -> 261 | F17: =F11*D17 -> 783 | K17: mỗi điểm sạc cho 3 xe/ngày
A20: TÍNH TOÁN SỐ LƯỢNG XE OTO | D20: TIÊU CHUẨN | E20: YÊU CẦU | F20: PATK | G20: ĐÁP ỨNG | K20: ghi chú
A21: Tổng diện tích đỗ xe hữu dụng | E21: =D6 -> 8489.885 | F21: =I6 -> 12240
A22: Diện tích đỗ ô tô hữu dụng | E22: =E21-E11 -> 5879.885 | F22: =F21-F11 -> 9630
A23: Tổng số slot đỗ ô tô cần đáp ứng | D23: 25 | E23: =E22/D23 -> 235.1954 | F23: =F22/D23 -> 385.2 | H23: =F23/4 -> 96.3
A28: Slot trạm sạc xe điện nếu có (30% tổng số ô tô) | D28: 0.3 | E28: =E23*D28 -> 70.55862 | F28: =F23*D28 -> 115.56
E32: =4420*0.9 -> 3978
A35: HẦM | B35: XE MÁY | C35: Ô TÔ | D35: TỔNG
A36: B1 | B36: 183 | C36: 34 | D36: =B36+C36 -> 217 | K36: 20/11/2026 | L36: =K36+11 -> #VALUE!
A37: B2 | B37: 292 | C37: 8 | D37: =B37+C37 -> 300
A38: B3 | B38: 195 | C38: 34 | D38: =B38+C38 -> 229
A39: B4 | B39: 216 | C39: 24 | D39: =B39+C39 -> 240
B40: =SUM(B36:B39) -> 886 | C40: =SUM(C36:C39) -> 100 | D40: =SUM(D36:D39) -> 986

Sheet TẦNG 1-6(HH)
A1: BẢNG THỐNG KÊ TẦNG 1-6 (HH)
A2: Tên căn | B2: Tầng 1 (m2) | C2: Tầng 2 (m2) | D2: Tầng 3 (m2) | E2: Tầng 4 (m2) | F2: Tầng 5 (m2) | G2: Tầng 6 (m2) | H2: Tổng diện tích(m2) | I2: ghi chú
A3: CĂN DV1 | B3: 67.9 | C3: 68.5 | D3: 68.5 | H3: =SUM(B3:G3) -> 204.9
A4: CĂN DV2 | B4: 68 | C4: 68.6 | D4: 68.6 | H4: =SUM(B4:G4) -> 205.2
A5: CĂN DV3 | B5: 93.8 | C5: 93.5 | D5: 94.6 | H5: =SUM(B5:G5) -> 281.9
A6: CĂN DV4 | B6: 94.3 | C6: 93.9 | D6: 95 | H6: =SUM(B6:G6) -> 283.2
A7: CĂN DV5 | B7: 83.3 | C7: 94.5 | D7: 141.4 | H7: =SUM(B7:G7) -> 319.2
A8: CĂN DV6 | B8: 94.3 | C8: 105.4 | D8: 105.4 | H8: =SUM(B8:G8) -> 305.1
A9: CĂN DV7 | B9: 65.3 | C9: 65.9 | D9: 65.9 | H9: =SUM(B9:G9) -> 197.1
A10: CĂN DV8 | B10: 97.2 | C10: 97.3 | D10: 98.5 | H10: =SUM(B10:G10) -> 293
A11: CĂN DV9 | B11: 82.2 | C11: 82.1 | D11: 82.1 | H11: =SUM(B11:G11) -> 246.4
A12: CĂN DV10 | B12: 81.5 | C12: 82.1 | D12: 82.6 | H12: =SUM(B12:G12) -> 246.2
A13: CĂN DV11 | B13: 81.9 | C13: 81.4 | D13: 81.4 | H13: =SUM(B13:G13) -> 244.7
A14: CĂN DV12 | B14: 81.7 | C14: 80.2 | D14: 80.2 | H14: =SUM(B14:G14) -> 242.1
... A17: CĂN DV15 | B17: 54 | C17: 54.7 | D17: 55.5 | H17: =SUM(B17:G17) -> 164.2
A18: VP QUẢN LÝ | D18: 39.8 | H18: =SUM(B18:G18) -> 39.8
A19: VP CHO THUÊ | E19: 1125.8 | F19: 1125.8 | H19: =SUM(B19:G19) -> 2251.6
A20: KHU VỆ SINH | E20: 40.1 | F20: 40.1
A21: TIỆN ÍCH THỂ THAO, BỂ BƠI | G21: =205+95+570 -> 870 | H21: =SUM(B21:G21) -> 870
A22: Tổng | B22: =SUM(B3:B21) -> 1187.9 | C22: =SUM(C3:C21) -> 1213.5 | D22: =SUM(D3:D21) -> 1304.6 | E22: =SUM(E3:E21) -> 1165.9 | F22: =SUM(F3:F21) -> 1165.9 | G22: =SUM(G3:G21) -> 870 | H22: =SUM(H3:H19) -> 5957.6
A23: Diện tích tường xây, giao thông hộp kĩ thuật,...(m2)
A24: Diện tích sàn tầng điển hình (m2) | M24: =M25/NHA_NOXH!D43 -> 0.13499657
M25: =1780*5 -> 8900

Sheet TẦNG 7-35(NOXH)
A1: Loại | B1: BẢNG THỐNG KÊ TẦNG ĐIỂN HÌNH (3-18), (20-35)
B2: Diện tích thông thủy (m2)/căn | C2: Số lượng (căn) | D2: Diện tích thông thủy (m2)/tầng | E2: Tỷ lệ | F2: Dân số/loại | G2: Dân số/tầng | H2: Loại căn
A3: 25-40 | D3: =B3*C3 -> 0 | E3: =D3/D14 -> 0 | F3: 1 | G3: =$F$3*C3 -> 0 | H3: 1PN
G4: =$F$3*C4 -> 0
G5: =$F$3*C5 -> 0
A6: 40-55 | D6: =B6*C6 -> 0 | E6: =D6/D14 -> 0 | F6: 2 | G6: =$F$6*C6 -> 0 | H6: 2PN
D7: =B7*C7 -> 0 | E7: =D7/D14 -> 0 | G7: =$F$6*C7 -> 0 | H7: 2PN
G8: =$F$6*C8 -> 0
A9: 55-70 | B9: 70 | C9: 14 | D9: =C9*B9 -> 980 | E9: =D9/D14 -> 0.92715232 | F9: 3 | G9: =$F$9*C9 -> 42 | H9: 2PN
D10: =C10*B10 -> 0 | E10: =D10/D14 -> 0 | G10: =$F$9*C10 -> 0 | H10: 2PN
D11: =C11*B11 -> 0 | E11: =D11/D14 -> 0 | G11: =$F$9*C11 -> 0 | H11: 2PN
A12: 70-77 | B12: 77 | C12: 1 | D12: =C12*B12 -> 77 | E12: =D12/D14 -> 0.072847682 | F12: 4 | G12: =$F$12*C12 -> 4 | J12: =F9*14 -> 42
A14: Tổng | C14: =SUM(C3:C13) -> 15 | D14: =SUM(D3:D13) -> 1057 | E14: =SUM(E3:E13) -> 1 | G14: =SUM(G3:G13) -> 46
A15: Diện tích sàn tầng điển hình (m2) | D15: 1450
A16: Hiệu suất sử dụng | D16: =D14/D15 -> 0.72896552

Sheet TẦNG 7-35(NOXH) (2)
A1: BẢNG THỐNG KÊ DIỆN TÍCH CĂN HỘ TẦNG ĐIỂN HÌNH
A2: STT | B2: Tên căn hộ | C2: Diện tích thông thủy (m2)/căn | D2: Số lượng (Căn) | E2: Diện tích tường xây, giao thông, hộp kĩ thuật (m2) | F2: Loại căn
A3: 1 | B3: CH-01 | C3: 69.5 | D3: 1 | E3: =C19-C18 -> 387.9 | F3: 3 NGỦ
A4: 2 | B4: CH-02 | C4: 69.5 | D4: =D3 -> 1 | F4: 2 NGỦ
A5: 3 | B5: CH-03 | C5: 69.8 | D5: =D4 -> 1 | F5: 2 NGỦ
A6: 4 | B6: CH-04 | C6: 78.2 | D6: =D5 -> 1 | F6: 3 NGỦ
A7: 5 | B7: CH-05 | C7: 69.4 | D7: =D6 -> 1 | F7: 3 NGỦ
A8: 6 | B8: CH-06 | C8: 69.2 | D8: =D7 -> 1 | F8: 2 NGỦ
A9: 7 | B9: CH-07 | C9: 69.4 | D9: =D8 -> 1 | F9: 2 NGỦ
A10: 8 | B10: CH-08 | C10: 68.9 | D10: =D9 -> 1 | F10: 2 NGỦ
A11: 9 | B11: CH-09 | C11: 68.2 | D11: =D10 -> 1 | F11: 3 NGỦ
A12: 10 | B12: CH-10 | C12: 68.5 | D12: =D11 -> 1 | F12: 2 NGỦ
A13: 11 | B13: CH-11 | C13: 69.4 | D13: =D12 -> 1 | F13: 3 NGỦ
A14: 12 | B14: CH-12 | C14: 68.7 | D14: =D13 -> 1 | F14: 2 NGỦ
A15: 13 | B15: CH-13 | C15: 67.8 | D15: =D14 -> 1 | F15: 2 NGỦ
... A17: 15 | B17: CH-15 | C17: 69.5 | D17: =D16 -> 1 | F17: 3 NGỦ
B18: TỔNG | C18: =SUM(C3:C17) -> 1045.2 | D18: =SUM(D3:D17) -> 15
B19: DIỆN TÍCH SÀN XÂY DỰNG (m2) | C19: 1433.1
B20: HIỆU SUẤT SỬ DỤNG (%) | C20: =C18/C19*100 -> 72.932803

Sheet BANG CT SS
B2: BẢNG CHỈ TIÊU QUY HOẠCH SỬ DỤNG ĐẤT TRƯỚC VÀ SAU ĐIỀU CHỈNH
B3: TT | C3: Hạng mục | D3: Theo QHCT, tỷ lệ 1/500 đã được UBND Q.Cầu Giấy phê duyệt | E3: Theo QHPK H2-2 | F3: Theo VB số 6725/QHKT-NSH ngày 24/12/2025 | G3: Nội dung đề xuất dự án | H3: Ghi chú
B5: 1 | C5: Ký hiệu ô đất quy hoạch | D5: N01 | F5: =+D5 -> N01 | G5: =+F5 -> N01 | H5: Phù hợp
B6: 2 | C6: Chức năng sử dụng đất | D6: Nhà ở cao tầng | E6: Nhà ở cao tầng | F6: Nhà ở xã hội | G6: Nhà ở xã hội
B7: 3 | C7: Diện tích nghiên cứu lập quy hoạch | D7: 4220 | E7: =+D7 -> 4220 | F7: 4220 | G7: 4220 | H7: Phù hợp
B8: 4 | C8: Diện tích xây dựng công trình | D8: =+D9+D10 -> 1589 | F8: =+F9+F10 -> 1589 | G8: =+G9+G10 -> 2088.7
C9: - Nhà cao tầng | D9: 1139 | F9: =+D9 -> 1139 | G9: =+'CHỈ TIÊU QH'!E5 -> 1708.7
C10: - Nhà trẻ | D10: 450 | F10: =+D10 -> 450 | G10: 380 | H10: Đảm bảo kiến trúc tổng thể
B11: 5 | C11: Diện tích đất cây xanh, sân dường nội bộ | D11: 2631 | G11: =4220-G10-G9 -> 2131.3
B12: 6 | C12: Tổng diện tích sàn xây dựng (không bao gồm diện tích sàn tầng hầm và tầng tum) | D12: =+D13+D14 -> 29375 | G12: =+G13+G14 -> 54346.7
C13: =+C9 -> - Nhà cao tầng | D13: =1139*25 -> 28475 | G13: =+'CHỈ TIÊU QH'!E10+'CHỈ TIÊU QH'!E20 -> 52960.7
C14: =+C10 -> - Nhà trẻ | D14: 900 | G14: =+'CHỈ TIÊU QH'!F9 -> 1386 | H14: Bổ sung diện tích theo phần tăng dân số
B15: 7 | C15: Tổng diện tích sàn tầng hầm | G15: =+'CHỈ TIÊU QH'!E18 -> 14400 | H15: Đáp ứng nhu cầu đỗ xe
B16: 8 | C16: Mật độ xây dựng chung | D16: 0.38 | E16: 0.45 | G16: =+G8/G7 -> 0.49495261 | H16: MĐXD bao gồm Nhà cao tầng + Nhà trẻ
C17: =+C13 -> - Nhà cao tầng | G17: =+'CHỈ TIÊU QH'!#REF!/100 -> #REF!
C18: =+C14 -> - Nhà trẻ | G18: =+G10/F10%/100 -> 0.84444444
B19: 9 | C19: Hệ số sử dụng đất | D19: 9.38 | G19: =+(G12/G7) -> 12.878365 | H19: Phù hợp QCXD - 01
C20: =+C17 -> - Nhà cao tầng | G20: =+'CHỈ TIÊU QH'!#REF! -> #REF!
C21: =+C18 -> - Nhà trẻ | G21: =+G14/F10 -> 3.08
B22: 10 | C22: Số tầng cao (không tính tầng tum, tầng hầm) | D22: 25 tầng | E22: Tối đa 35 tầng | F22: 35 tầng | G22: =+F22 -> 35 tầng
C23: =+C9 -> - Nhà cao tầng | D23: 25 | F23: 35 | G23: 35 | H23: Phù hợp
C24: =+C10 -> - Nhà trẻ | D24: 2 | F24: 2 | G24: 3 | H24: Phù hợp QCXD - 01
B25: 11 | C25: Số căn hộ/ nhà | D25: 230 | G25: 420 | H25: Tính toán theo quyết định số 34/2024/QĐ-UBND ngày 27/5/2024 của UBND Thành phố
B26: 12 | C26: Dân số | G26: 1288
D30: =1139*2.2 -> 2505.8 | G30: =1288/1000*55*12 -> 850.08

Sheet CÂN BẰNG SỬ DỤNG ĐẤT 
A2: BẢNG CÂN BẰNG QUY HOẠCH SỬ DỤNG ĐẤT
A3: TT | B3: LOẠI ĐẤT | C3: DIỆN TÍCH ĐẤT | D3: TỶ LỆ | E3: CHIỀU CAO CÔNG TRÌNH TỐI ĐA ( Văn bản số 880/TC-QC ngày 12/08/2026)
C4: (m2) | D4: % | E4: (m)
B5: TỔNG DIỆN TÍCH QUY HOẠCH | C5: 4397 | D5: 100
A6: 1 | B6: ĐẤT XÂY DỰNG CÔNG TRÌNH | C6: ='Bảng số liệu quy hoạch'!D11 -> 2053.7 | D6: =C6/C5*100 -> 46.706846 | E6: 138.35
A7: 2 | B7: ĐẤT CÂY XANH, GIAO THÔNG, SÂN, ĐƯỜNG | C7: =C5-C6 -> 2343.3 | D7: =C7/C5*100 -> 53.293154

Sheet Bảng số liệu quy hoạch
A1: STT | B1: HẠNG MỤC | C1: ĐƠN VỊ | D1: SỐ LIỆU | E1: Ghi chú
A2: 1 | B2: Diện tích đất nghiên cứu lập quy hoạch tổng mặt bằng | C2: m2 | D2: 4397
B3: Diện tích đất xây dựng trường mầm non | C3: m2 | D3: 420
B4: Diện tích đất xây dựng nhà ở cho cán bộ chiến sĩ | C4: m2 | D4: =D2-D3 -> 3977
A5: 2 | B5: Mật độ xây dựng (gộp) | C5: % | D5: =D11/D2*100 -> 46.706846 | E5: Bao gồm diện tích xây dựng nhà ở cho cán bộ chiến sĩ và trường mầm non
A6: 3 | B6: Tầng cao công trình | C6: Tầng | D6: 04 tầng và 35 tầng
B7: Trường mầm non | C7: Tầng | D7: 04 tầng | E7: Phù hợp QCXDVN, thông tư của bộ giáo dục và đào tạo (văn bản hợp nhất số 14)
B8: Nhà ở cho cán bộ chiến sĩ | C8: Tầng | D8: 35 tầng
A9: 4 | B9: Tầng hầm | C9: Tầng | D9: 4
B10: Nhà ở cho cán bộ chiến sĩ | C10: Tầng | D10: 4
A11: 5 | B11: Tổng diện tích xây dựng | C11: m2 | D11: =D12+D13 -> 2053.7
B12: Trường mầm non | C12: m2 | D12: 273.7
B13: Nhà ở cho cán bộ chiến sĩ | C13: m2 | D13: 1780
A14: 6 | B14: Tổng diện tích xây dựng sàn nổi | C14: m2 | D14: =D15+D16 -> 52622.4
B15: Nhà ở cho cán bộ chiến sĩ | C15: m2 | D15: =NHA_NOXH!O20 -> 51527.6
B16: Trường mầm non | C16: m2 | D16: =D12*4 -> 1094.8
A17: 7 | B17: Tổng diện tích xây dựng sàn hầm | C17: m2 | D17: =HẦM!E6 -> 14400
A18: 8 | B18: Hệ số sử dụng đất | C18: Lần | D18: =D14/D2 -> 11.967796 | E18: Bao gồm diện tích xây dựng nhà ở cho cán bộ chiến sĩ và trường mầm non
A19: 9 | B19: Số lượng căn hộ | C19: Căn | D19: 420
A20: 10 | B20: Dân số dự kiến | C20: Người | D20: 1288

Sheet NHA_DVTM
A1: BẢNG CHỈ TIÊU CÔNG TRÌNH NOXH
B2: TÊN CĂN | C2: DIỆN TÍCH (m2) | D2: MẬT ĐỘ (%) | E2: TỔNG DIỆN TÍCH | F2: TẦNG CAO | G2: TỔNG DIỆN TÍCH(căn) | H2: TỔNG MĐXD | I2: SỐ LƯỢNG
B3: A1 | C3: 159.2 | D3: 75 | E3: =C3*D3/100 -> 119.4 | F3: 5 | G3: =F3*E3 -> 597 | I3: 1
B4: A2 | C4: =C13 -> 78 | D4: 90 | E4: =C4*D4/100 -> 70.2 | F4: 5 | G4: =F4*E4 -> 351 | I4: 1
B5: A3 | C5: =C14 -> 78 | D5: =D4 -> 90 | E5: =C5*D5/100 -> 70.2 | F5: 5 | G5: =F5*E5 -> 351 | I5: 1
B6: A4 | C6: =C15 -> 78 | D6: =D5 -> 90 | E6: =C6*D6/100 -> 70.2 | F6: 5 | G6: =F6*E6 -> 351 | I6: 1
B7: A5 | C7: =C16 -> 78 | D7: =D6 -> 90 | E7: =C7*D7/100 -> 70.2 | F7: 5 | G7: =F7*E7 -> 351 | I7: 1
B8: A6 | C8: =C17 -> 78 | D8: =D7 -> 90 | E8: =C8*D8/100 -> 70.2 | F8: 5 | G8: =F8*E8 -> 351 | I8: 1
B9: A7 | C9: =C18 -> 78 | D9: =D8 -> 90 | E9: =C9*D9/100 -> 70.2 | F9: 5 | G9: =F9*E9 -> 351 | I9: 1
B10: A8 | C10: =C11 -> 117 | D10: 80 | E10: =C10*D10/100 -> 93.6 | F10: 5 | G10: =F10*E10 -> 468 | I10: 1
B11: B1 | C11: =C19 -> 117 | D11: 80 | E11: =C11*D11/100 -> 93.6 | F11: 5 | G11: =F11*E11 -> 468 | I11: 1
B12: B2 | C12: =C13 -> 78 | D12: =D4 -> 90 | E12: =C12*D12/100 -> 70.2 | F12: 5 | G12: =F12*E12 -> 351 | I12: 1
B13: B3 | C13: =C14 -> 78 | D13: =D5 -> 90 | E13: =C13*D13/100 -> 70.2 | F13: 5 | G13: =F13*E13 -> 351 | I13: 1
B14: B4 | C14: =C15 -> 78 | D14: =D6 -> 90 | E14: =C14*D14/100 -> 70.2 | F14: 5 | G14: =F14*E14 -> 351 | I14: 1
B15: B5 | C15: =C16 -> 78 | D15: =D7 -> 90 | E15: =C15*D15/100 -> 70.2 | F15: 5 | G15: =F15*E15 -> 351 | I15: 1
B16: B6 | C16: =C17 -> 78 | D16: =D8 -> 90 | E16: =C16*D16/100 -> 70.2 | F16: 5 | G16: =F16*E16 -> 351 | I16: 1
B17: B7 | C17: =C18 -> 78 | D17: =D9 -> 90 | E17: =C17*D17/100 -> 70.2 | F17: 5 | G17: =F17*E17 -> 351 | I17: 1
B18: B8 | C18: 78 | D18: =D17 -> 90 | E18: =C18*D18/100 -> 70.2 | F18: 5 | G18: =F18*E18 -> 351 | I18: 1
B19: B9 | C19: 117 | D19: 80 | E19: =C19*D19/100 -> 93.6 | F19: 5 | G19: =F19*E19 -> 468 | I19: 1
B20: C1 | C20: 170.4 | D20: 75 | E20: =C20*D20/100 -> 127.8 | F20: 5 | G20: =F20*E20 -> 639 | I20: 1
B21: C2 | C21: =C22 -> 91 | D21: 85 | E21: =C21*D21/100 -> 77.35 | F21: 5 | G21: =F21*E21 -> 386.75 | I21: 1
B22: C3 | C22: =C23 -> 91 | D22: =D21 -> 85 | E22: =C22*D22/100 -> 77.35 | F22: 5 | G22: =F22*E22 -> 386.75 | I22: 1
B23: C4 | C23: =C24 -> 91 | D23: =D22 -> 85 | E23: =C23*D23/100 -> 77.35 | F23: 5 | G23: =F23*E23 -> 386.75 | I23: 1
B24: D1 | C24: =C25 -> 91 | D24: =D23 -> 85 | E24: =C24*D24/100 -> 77.35 | F24: 5 | G24: =F24*E24 -> 386.75 | I24: 1
B25: D2 | C25: =C26 -> 91 | D25: =D24 -> 85 | E25: =C25*D25/100 -> 77.35 | F25: 5 | G25: =F25*E25 -> 386.75 | I25: 1
B26: D3 | C26: 91 | D26: =D25 -> 85 | E26: =C26*D26/100 -> 77.35 | F26: 5 | G26: =F26*E26 -> 386.75 | I26: 1
B27: D4 | C27: 107.8 | D27: 85 | E27: =C27*D27/100 -> 91.63 | F27: 5 | G27: =F27*E27 -> 458.15 | I27: 1
A28: Tổng | C28: =SUM(C3:C27) -> 2348.4 | E28: =SUM(E3:E27) -> 1996.33 | G28: =SUM(G3:G27) -> 9981.65 | H28: =E28/C28*100 -> 85.008091 | I28: =SUM(I3:I27) -> 25
K35: {=#REF!} -> #REF!
